<mujoco model="bouncing ball">
  <size nconmax="300" njmax="500"/>
  <option timestep="0.01" />
  <option gravity="0 0 -98.1"/>
  <statistic center="5 0 5" extent="20"/>
  <visual>
    <headlight diffuse="0.6 0.6 0.6" ambient="0.1 0.1 0.1" specular="0 0 0"/>
    <rgba haze="0.15 0.25 0.35 1"/>
    <global azimuth="90" elevation="0"/>
  </visual>

  <asset>
    <texture type="skybox" builtin="gradient" rgb1="0.3 0.5 0.7" rgb2="0 0 0" width="512" height="3072"/>
    <texture type="2d" name="groundplane" builtin="checker" mark="edge" rgb1="0.2 0.3 0.4" rgb2="0.1 0.2 0.3"
      markrgb="0.8 0.8 0.8" width="300" height="300"/>
    <material name="groundplane" texture="groundplane" texuniform="true" texrepeat="1 1" reflectance="0.2"/>
    <material name="blue_" rgba="0 0 1 1" />
    <material name="green" rgba="0 1 0 1" />
    <material name="red__" rgba="1 0 0 1" />
    <material name="white" rgba="1 1 1 1" />
  </asset>

  <worldbody>
    <light pos="0 0 10" dir="0 0 -1" directional="true"/>
    <geom name="floor" size="0 0 0.05" type="plane" material="groundplane" solref="0.01 0.5" />
    
    <body name="basket_base" pos="0 0 0">
      <joint name="basket_joint" type="slide" axis="0 1 0"/>
      <body name="basket_floating" pos="0 0 0" mocap="true">
        <geom name="wall1" type="box" size="0.1 1 0.5" pos="1.1 0 0.5" material="green"/>
        <geom name="wall2" type="box" size="0.1 1 0.5" pos="-1.1 0 0.5" material="green"/>
        <geom name="wall3" type="box" size="1.2 0.1 0.5" pos="0 1.1 0.5" material="green"/>
        <geom name="wall4" type="box" size="1.2 0.1 0.5" pos="0 -1.1 0.5" material="green"/>
      </body>
    </body>

    <body name="ball" pos="10 0 5">
      <joint type="free"/>
      <geom name="ball" type="sphere" size="0.4" density="0.5" material="red__" solref="0.01 0.5" />
    </body>
  </worldbody>
</mujoco>
